Workbook

Sheet Rates
A1: Date | B1: USD/INR rate | C1: USD/INR index (start=100) | D1: USD/INR 30d average | E1: USD/INR trend | F1: USD/GBP rate | G1: USD/GBP index (start=100) | H1: USD/GBP 30d average | I1: USD/GBP trend | J1: Carried forward
A2: 45292 | B2: 80 | C2: =B2/B$2*100 | D2: ="" | E2: =SLOPE(B$2:B$731,$A$2:$A$731)*$A2+INTERCEPT(B$2:B$731,$A$2:$A$731) | F2: 0.79 | G2: =F2/F$2*100 | H2: ="" | I2: =SLOPE(F$2:F$731,$A$2:$A$731)*$A2+INTERCEPT(F$2:F$731,$A$2:$A$731)
A3: 45293 | B3: 80.01 | C3: =B3/B$2*100 | D3: ="" | E3: =SLOPE(B$2:B$731,$A$2:$A$731)*$A3+INTERCEPT(B$2:B$731,$A$2:$A$731) | F3: 0.79 | G3: =F3/F$2*100 | H3: ="" | I3: =SLOPE(F$2:F$731,$A$2:$A$731)*$A3+INTERCEPT(F$2:F$731,$A$2:$A$731)
A4: 45294 | B4: 80.02 | C4: =B4/B$2*100 | D4: ="" | E4: =SLOPE(B$2:B$731,$A$2:$A$731)*$A4+INTERCEPT(B$2:B$731,$A$2:$A$731) | F4: 0.79 | G4: =F4/F$2*100 | H4: ="" | I4: =SLOPE(F$2:F$731,$A$2:$A$731)*$A4+INTERCEPT(F$2:F$731,$A$2:$A$731)
A5: 45295 | B5: 80.03 | C5: =B5/B$2*100 | D5: ="" | E5: =SLOPE(B$2:B$731,$A$2:$A$731)*$A5+INTERCEPT(B$2:B$731,$A$2:$A$731) | F5: 0.79 | G5: =F5/F$2*100 | H5: ="" | I5: =SLOPE(F$2:F$731,$A$2:$A$731)*$A5+INTERCEPT(F$2:F$731,$A$2:$A$731)
A6: 45296 | B6: 80.04 | C6: =B6/B$2*100 | D6: ="" | E6: =SLOPE(B$2:B$731,$A$2:$A$731)*$A6+INTERCEPT(B$2:B$731,$A$2:$A$731) | F6: 0.79 | G6: =F6/F$2*100 | H6: ="" | I6: =SLOPE(F$2:F$731,$A$2:$A$731)*$A6+INTERCEPT(F$2:F$731,$A$2:$A$731)
A7: 45297 | B7: 80.05 | C7: =B7/B$2*100 | D7: ="" | E7: =SLOPE(B$2:B$731,$A$2:$A$731)*$A7+INTERCEPT(B$2:B$731,$A$2:$A$731) | F7: 0.79 | G7: =F7/F$2*100 | H7: ="" | I7: =SLOPE(F$2:F$731,$A$2:$A$731)*$A7+INTERCEPT(F$2:F$731,$A$2:$A$731) | J7: yes
A8: 45298 | B8: 80.06 | C8: =B8/B$2*100 | D8: ="" | E8: =SLOPE(B$2:B$731,$A$2:$A$731)*$A8+INTERCEPT(B$2:B$731,$A$2:$A$731) | F8: 0.79 | G8: =F8/F$2*100 | H8: ="" | I8: =SLOPE(F$2:F$731,$A$2:$A$731)*$A8+INTERCEPT(F$2:F$731,$A$2:$A$731) | J8: yes
A9: 45299 | B9: 80.07 | C9: =B9/B$2*100 | D9: ="" | E9: =SLOPE(B$2:B$731,$A$2:$A$731)*$A9+INTERCEPT(B$2:B$731,$A$2:$A$731) | F9: 0.79 | G9: =F9/F$2*100 | H9: ="" | I9: =SLOPE(F$2:F$731,$A$2:$A$731)*$A9+INTERCEPT(F$2:F$731,$A$2:$A$731)
A10: 45300 | B10: 80.08 | C10: =B10/B$2*100 | D10: ="" | E10: =SLOPE(B$2:B$731,$A$2:$A$731)*$A10+INTERCEPT(B$2:B$731,$A$2:$A$731) | F10: 0.79 | G10: =F10/F$2*100 | H10: ="" | I10: =SLOPE(F$2:F$731,$A$2:$A$731)*$A10+INTERCEPT(F$2:F$731,$A$2:$A$731)
A11: 45301 | B11: 80.09 | C11: =B11/B$2*100 | D11: ="" | E11: =SLOPE(B$2:B$731,$A$2:$A$731)*$A11+INTERCEPT(B$2:B$731,$A$2:$A$731) | F11: 0.79 | G11: =F11/F$2*100 | H11: ="" | I11: =SLOPE(F$2:F$731,$A$2:$A$731)*$A11+INTERCEPT(F$2:F$731,$A$2:$A$731)
A12: 45302 | B12: 80.1 | C12: =B12/B$2*100 | D12: ="" | E12: =SLOPE(B$2:B$731,$A$2:$A$731)*$A12+INTERCEPT(B$2:B$731,$A$2:$A$731) | F12: 0.79 | G12: =F12/F$2*100 | H12: ="" | I12: =SLOPE(F$2:F$731,$A$2:$A$731)*$A12+INTERCEPT(F$2:F$731,$A$2:$A$731)
A13: 45303 | B13: 80.11 | C13: =B13/B$2*100 | D13: ="" | E13: =SLOPE(B$2:B$731,$A$2:$A$731)*$A13+INTERCEPT(B$2:B$731,$A$2:$A$731) | F13: 0.79 | G13: =F13/F$2*100 | H13: ="" | I13: =SLOPE(F$2:F$731,$A$2:$A$731)*$A13+INTERCEPT(F$2:F$731,$A$2:$A$731)
A14: 45304 | B14: 80.12 | C14: =B14/B$2*100 | D14: ="" | E14: =SLOPE(B$2:B$731,$A$2:$A$731)*$A14+INTERCEPT(B$2:B$731,$A$2:$A$731) | F14: 0.79 | G14: =F14/F$2*100 | H14: ="" | I14: =SLOPE(F$2:F$731,$A$2:$A$731)*$A14+INTERCEPT(F$2:F$731,$A$2:$A$731) | J14: yes
A15: 45305 | B15: 80.13 | C15: =B15/B$2*100 | D15: ="" | E15: =SLOPE(B$2:B$731,$A$2:$A$731)*$A15+INTERCEPT(B$2:B$731,$A$2:$A$731) | F15: 0.79 | G15: =F15/F$2*100 | H15: ="" | I15: =SLOPE(F$2:F$731,$A$2:$A$731)*$A15+INTERCEPT(F$2:F$731,$A$2:$A$731) | J15: yes
A16: 45306 | B16: 80.14 | C16: =B16/B$2*100 | D16: ="" | E16: =SLOPE(B$2:B$731,$A$2:$A$731)*$A16+INTERCEPT(B$2:B$731,$A$2:$A$731) | F16: 0.79 | G16: =F16/F$2*100 | H16: ="" | I16: =SLOPE(F$2:F$731,$A$2:$A$731)*$A16+INTERCEPT(F$2:F$731,$A$2:$A$731)
A17: 45307 | B17: 80.15 | C17: =B17/B$2*100 | D17: ="" | E17: =SLOPE(B$2:B$731,$A$2:$A$731)*$A17+INTERCEPT(B$2:B$731,$A$2:$A$731) | F17: 0.79 | G17: =F17/F$2*100 | H17: ="" | I17: =SLOPE(F$2:F$731,$A$2:$A$731)*$A17+INTERCEPT(F$2:F$731,$A$2:$A$731)
A18: 45308 | B18: 80.16 | C18: =B18/B$2*100 | D18: ="" | E18: =SLOPE(B$2:B$731,$A$2:$A$731)*$A18+INTERCEPT(B$2:B$731,$A$2:$A$731) | F18: 0.79 | G18: =F18/F$2*100 | H18: ="" | I18: =SLOPE(F$2:F$731,$A$2:$A$731)*$A18+INTERCEPT(F$2:F$731,$A$2:$A$731)
A19: 45309 | B19: 80.17 | C19: =B19/B$2*100 | D19: ="" | E19: =SLOPE(B$2:B$731,$A$2:$A$731)*$A19+INTERCEPT(B$2:B$731,$A$2:$A$731) | F19: 0.79 | G19: =F19/F$2*100 | H19: ="" | I19: =SLOPE(F$2:F$731,$A$2:$A$731)*$A19+INTERCEPT(F$2:F$731,$A$2:$A$731)
A20: 45310 | B20: 80.18 | C20: =B20/B$2*100 | D20: ="" | E20: =SLOPE(B$2:B$731,$A$2:$A$731)*$A20+INTERCEPT(B$2:B$731,$A$2:$A$731) | F20: 0.79 | G20: =F20/F$2*100 | H20: ="" | I20: =SLOPE(F$2:F$731,$A$2:$A$731)*$A20+INTERCEPT(F$2:F$731,$A$2:$A$731)
A21: 45311 | B21: 80.19 | C21: =B21/B$2*100 | D21: ="" | E21: =SLOPE(B$2:B$731,$A$2:$A$731)*$A21+INTERCEPT(B$2:B$731,$A$2:$A$731) | F21: 0.79 | G21: =F21/F$2*100 | H21: ="" | I21: =SLOPE(F$2:F$731,$A$2:$A$731)*$A21+INTERCEPT(F$2:F$731,$A$2:$A$731) | J21: yes
A22: 45312 | B22: 80.2 | C22: =B22/B$2*100 | D22: ="" | E22: =SLOPE(B$2:B$731,$A$2:$A$731)*$A22+INTERCEPT(B$2:B$731,$A$2:$A$731) | F22: 0.79 | G22: =F22/F$2*100 | H22: ="" | I22: =SLOPE(F$2:F$731,$A$2:$A$731)*$A22+INTERCEPT(F$2:F$731,$A$2:$A$731) | J22: yes
A23: 45313 | B23: 80.21 | C23: =B23/B$2*100 | D23: ="" | E23: =SLOPE(B$2:B$731,$A$2:$A$731)*$A23+INTERCEPT(B$2:B$731,$A$2:$A$731) | F23: 0.79 | G23: =F23/F$2*100 | H23: ="" | I23: =SLOPE(F$2:F$731,$A$2:$A$731)*$A23+INTERCEPT(F$2:F$731,$A$2:$A$731)
A24: 45314 | B24: 80.22 | C24: =B24/B$2*100 | D24: ="" | E24: =SLOPE(B$2:B$731,$A$2:$A$731)*$A24+INTERCEPT(B$2:B$731,$A$2:$A$731) | F24: 0.79 | G24: =F24/F$2*100 | H24: ="" | I24: =SLOPE(F$2:F$731,$A$2:$A$731)*$A24+INTERCEPT(F$2:F$731,$A$2:$A$731)
A25: 45315 | B25: 80.23 | C25: =B25/B$2*100 | D25: ="" | E25: =SLOPE(B$2:B$731,$A$2:$A$731)*$A25+INTERCEPT(B$2:B$731,$A$2:$A$731) | F25: 0.79 | G25: =F25/F$2*100 | H25: ="" | I25: =SLOPE(F$2:F$731,$A$2:$A$731)*$A25+INTERCEPT(F$2:F$731,$A$2:$A$731)
A26: 45316 | B26: 80.24 | C26: =B26/B$2*100 | D26: ="" | E26: =SLOPE(B$2:B$731,$A$2:$A$731)*$A26+INTERCEPT(B$2:B$731,$A$2:$A$731) | F26: 0.79 | G26: =F26/F$2*100 | H26: ="" | I26: =SLOPE(F$2:F$731,$A$2:$A$731)*$A26+INTERCEPT(F$2:F$731,$A$2:$A$731)
A27: 45317 | B27: 80.25 | C27: =B27/B$2*100 | D27: ="" | E27: =SLOPE(B$2:B$731,$A$2:$A$731)*$A27+INTERCEPT(B$2:B$731,$A$2:$A$731) | F27: 0.79 | G27: =F27/F$2*100 | H27: ="" | I27: =SLOPE(F$2:F$731,$A$2:$A$731)*$A27+INTERCEPT(F$2:F$731,$A$2:$A$731)
A28: 45318 | B28: 80.26 | C28: =B28/B$2*100 | D28: ="" | E28: =SLOPE(B$2:B$731,$A$2:$A$731)*$A28+INTERCEPT(B$2:B$731,$A$2:$A$731) | F28: 0.79 | G28: =F28/F$2*100 | H28: ="" | I28: =SLOPE(F$2:F$731,$A$2:$A$731)*$A28+INTERCEPT(F$2:F$731,$A$2:$A$731) | J28: yes
A29: 45319 | B29: 80.27 | C29: =B29/B$2*100 | D29: ="" | E29: =SLOPE(B$2:B$731,$A$2:$A$731)*$A29+INTERCEPT(B$2:B$731,$A$2:$A$731) | F29: 0.79 | G29: =F29/F$2*100 | H29: ="" | I29: =SLOPE(F$2:F$731,$A$2:$A$731)*$A29+INTERCEPT(F$2:F$731,$A$2:$A$731) | J29: yes
A30: 45320 | B30: 80.28 | C30: =B30/B$2*100 | D30: ="" | E30: =SLOPE(B$2:B$731,$A$2:$A$731)*$A30+INTERCEPT(B$2:B$731,$A$2:$A$731) | F30: 0.79 | G30: =F30/F$2*100 | H30: ="" | I30: =SLOPE(F$2:F$731,$A$2:$A$731)*$A30+INTERCEPT(F$2:F$731,$A$2:$A$731)
A31: 45321 | B31: 80.29 | C31: =B31/B$2*100 | D31: =AVERAGE(B2:B31) | E31: =SLOPE(B$2:B$731,$A$2:$A$731)*$A31+INTERCEPT(B$2:B$731,$A$2:$A$731) | F31: 0.79 | G31: =F31/F$2*100 | H31: =AVERAGE(F2:F31) | I31: =SLOPE(F$2:F$731,$A$2:$A$731)*$A31+INTERCEPT(F$2:F$731,$A$2:$A$731)
A32: 45322 | B32: 80.3 | C32: =B32/B$2*100 | D32: =AVERAGE(B3:B32) | E32: =SLOPE(B$2:B$731,$A$2:$A$731)*$A32+INTERCEPT(B$2:B$731,$A$2:$A$731) | F32: 0.79 | G32: =F32/F$2*100 | H32: =AVERAGE(F3:F32) | I32: =SLOPE(F$2:F$731,$A$2:$A$731)*$A32+INTERCEPT(F$2:F$731,$A$2:$A$731)
A33: 45323 | B33: 80.31 | C33: =B33/B$2*100 | D33: =AVERAGE(B4:B33) | E33: =SLOPE(B$2:B$731,$A$2:$A$731)*$A33+INTERCEPT(B$2:B$731,$A$2:$A$731) | F33: 0.79 | G33: =F33/F$2*100 | H33: =AVERAGE(F4:F33) | I33: =SLOPE(F$2:F$731,$A$2:$A$731)*$A33+INTERCEPT(F$2:F$731,$A$2:$A$731)
A34: 45324 | B34: 80.32 | C34: =B34/B$2*100 | D34: =AVERAGE(B5:B34) | E34: =SLOPE(B$2:B$731,$A$2:$A$731)*$A34+INTERCEPT(B$2:B$731,$A$2:$A$731) | F34: 0.79 | G34: =F34/F$2*100 | H34: =AVERAGE(F5:F34) | I34: =SLOPE(F$2:F$731,$A$2:$A$731)*$A34+INTERCEPT(F$2:F$731,$A$2:$A$731)
A35: 45325 | B35: 80.33 | C35: =B35/B$2*100 | D35: =AVERAGE(B6:B35) | E35: =SLOPE(B$2:B$731,$A$2:$A$731)*$A35+INTERCEPT(B$2:B$731,$A$2:$A$731) | F35: 0.79 | G35: =F35/F$2*100 | H35: =AVERAGE(F6:F35) | I35: =SLOPE(F$2:F$731,$A$2:$A$731)*$A35+INTERCEPT(F$2:F$731,$A$2:$A$731) | J35: yes
A36: 45326 | B36: 80.34 | C36: =B36/B$2*100 | D36: =AVERAGE(B7:B36) | E36: =SLOPE(B$2:B$731,$A$2:$A$731)*$A36+INTERCEPT(B$2:B$731,$A$2:$A$731) | F36: 0.79 | G36: =F36/F$2*100 | H36: =AVERAGE(F7:F36) | I36: =SLOPE(F$2:F$731,$A$2:$A$731)*$A36+INTERCEPT(F$2:F$731,$A$2:$A$731) | J36: yes
A37: 45327 | B37: 80.35 | C37: =B37/B$2*100 | D37: =AVERAGE(B8:B37) | E37: =SLOPE(B$2:B$731,$A$2:$A$731)*$A37+INTERCEPT(B$2:B$731,$A$2:$A$731) | F37: 0.79 | G37: =F37/F$2*100 | H37: =AVERAGE(F8:F37) | I37: =SLOPE(F$2:F$731,$A$2:$A$731)*$A37+INTERCEPT(F$2:F$731,$A$2:$A$731)
A38: 45328 | B38: 80.36 | C38: =B38/B$2*100 | D38: =AVERAGE(B9:B38) | E38: =SLOPE(B$2:B$731,$A$2:$A$731)*$A38+INTERCEPT(B$2:B$731,$A$2:$A$731) | F38: 0.79 | G38: =F38/F$2*100 | H38: =AVERAGE(F9:F38) | I38: =SLOPE(F$2:F$731,$A$2:$A$731)*$A38+INTERCEPT(F$2:F$731,$A$2:$A$731)
A39: 45329 | B39: 80.37 | C39: =B39/B$2*100 | D39: =AVERAGE(B10:B39) | E39: =SLOPE(B$2:B$731,$A$2:$A$731)*$A39+INTERCEPT(B$2:B$731,$A$2:$A$731) | F39: 0.79 | G39: =F39/F$2*100 | H39: =AVERAGE(F10:F39) | I39: =SLOPE(F$2:F$731,$A$2:$A$731)*$A39+INTERCEPT(F$2:F$731,$A$2:$A$731)
A40: 45330 | B40: 80.38 | C40: =B40/B$2*100 | D40: =AVERAGE(B11:B40) | E40: =SLOPE(B$2:B$731,$A$2:$A$731)*$A40+INTERCEPT(B$2:B$731,$A$2:$A$731) | F40: 0.79 | G40: =F40/F$2*100 | H40: =AVERAGE(F11:F40) | I40: =SLOPE(F$2:F$731,$A$2:$A$731)*$A40+INTERCEPT(F$2:F$731,$A$2:$A$731)
...

Sheet Monthly
A1: Month start | B1: Month end | C1: USD/INR average | D1: USD/GBP average
A2: 45292 | B2: 45323 | C2: =AVERAGEIFS(Rates!B$2:B$731,Rates!$A$2:$A$731,">="&$A2,Rates!$A$2:$A$731,"<"&$B2) | D2: =AVERAGEIFS(Rates!F$2:F$731,Rates!$A$2:$A$731,">="&$A2,Rates!$A$2:$A$731,"<"&$B2)
A3: 45323 | B3: 45352 | C3: =AVERAGEIFS(Rates!B$2:B$731,Rates!$A$2:$A$731,">="&$A3,Rates!$A$2:$A$731,"<"&$B3) | D3: =AVERAGEIFS(Rates!F$2:F$731,Rates!$A$2:$A$731,">="&$A3,Rates!$A$2:$A$731,"<"&$B3)
A4: 45352 | B4: 45383 | C4: =AVERAGEIFS(Rates!B$2:B$731,Rates!$A$2:$A$731,">="&$A4,Rates!$A$2:$A$731,"<"&$B4) | D4: =AVERAGEIFS(Rates!F$2:F$731,Rates!$A$2:$A$731,">="&$A4,Rates!$A$2:$A$731,"<"&$B4)
A5: 45383 | B5: 45413 | C5: =AVERAGEIFS(Rates!B$2:B$731,Rates!$A$2:$A$731,">="&$A5,Rates!$A$2:$A$731,"<"&$B5) | D5: =AVERAGEIFS(Rates!F$2:F$731,Rates!$A$2:$A$731,">="&$A5,Rates!$A$2:$A$731,"<"&$B5)
A6: 45413 | B6: 45444 | C6: =AVERAGEIFS(Rates!B$2:B$731,Rates!$A$2:$A$731,">="&$A6,Rates!$A$2:$A$731,"<"&$B6) | D6: =AVERAGEIFS(Rates!F$2:F$731,Rates!$A$2:$A$731,">="&$A6,Rates!$A$2:$A$731,"<"&$B6)
A7: 45444 | B7: 45474 | C7: =AVERAGEIFS(Rates!B$2:B$731,Rates!$A$2:$A$731,">="&$A7,Rates!$A$2:$A$731,"<"&$B7) | D7: =AVERAGEIFS(Rates!F$2:F$731,Rates!$A$2:$A$731,">="&$A7,Rates!$A$2:$A$731,"<"&$B7)
A8: 45474 | B8: 45505 | C8: =AVERAGEIFS(Rates!B$2:B$731,Rates!$A$2:$A$731,">="&$A8,Rates!$A$2:$A$731,"<"&$B8) | D8: =AVERAGEIFS(Rates!F$2:F$731,Rates!$A$2:$A$731,">="&$A8,Rates!$A$2:$A$731,"<"&$B8)
A9: 45505 | B9: 45536 | C9: =AVERAGEIFS(Rates!B$2:B$731,Rates!$A$2:$A$731,">="&$A9,Rates!$A$2:$A$731,"<"&$B9) | D9: =AVERAGEIFS(Rates!F$2:F$731,Rates!$A$2:$A$731,">="&$A9,Rates!$A$2:$A$731,"<"&$B9)
A10: 45536 | B10: 45566 | C10: =AVERAGEIFS(Rates!B$2:B$731,Rates!$A$2:$A$731,">="&$A10,Rates!$A$2:$A$731,"<"&$B10) | D10: =AVERAGEIFS(Rates!F$2:F$731,Rates!$A$2:$A$731,">="&$A10,Rates!$A$2:$A$731,"<"&$B10)
A11: 45566 | B11: 45597 | C11: =AVERAGEIFS(Rates!B$2:B$731,Rates!$A$2:$A$731,">="&$A11,Rates!$A$2:$A$731,"<"&$B11) | D11: =AVERAGEIFS(Rates!F$2:F$731,Rates!$A$2:$A$731,">="&$A11,Rates!$A$2:$A$731,"<"&$B11)
A12: 45597 | B12: 45627 | C12: =AVERAGEIFS(Rates!B$2:B$731,Rates!$A$2:$A$731,">="&$A12,Rates!$A$2:$A$731,"<"&$B12) | D12: =AVERAGEIFS(Rates!F$2:F$731,Rates!$A$2:$A$731,">="&$A12,Rates!$A$2:$A$731,"<"&$B12)
A13: 45627 | B13: 45658 | C13: =AVERAGEIFS(Rates!B$2:B$731,Rates!$A$2:$A$731,">="&$A13,Rates!$A$2:$A$731,"<"&$B13) | D13: =AVERAGEIFS(Rates!F$2:F$731,Rates!$A$2:$A$731,">="&$A13,Rates!$A$2:$A$731,"<"&$B13)
... A25: 45992 | B25: 46023 | C25: =AVERAGEIFS(Rates!B$2:B$731,Rates!$A$2:$A$731,">="&$A25,Rates!$A$2:$A$731,"<"&$B25) | D25: =AVERAGEIFS(Rates!F$2:F$731,Rates!$A$2:$A$731,">="&$A25,Rates!$A$2:$A$731,"<"&$B25)

Sheet Methodology
A1: How this workbook was built
A3: Source | B3: synthetic fixture
A4: Retrieved | B4: 2026-08-16 18:42
A5: Base currency | B5: USD
A6: Quote currencies | B6: INR, GBP
A7: First published rate | B7: 2024-01-01
A8: Last published rate | B8: 2025-12-30
A9: Published business days | B9: 522
A10: Calendar days in sheet | B10: 730
A11: Days carried forward | B11: 208
A12: Cross-rate caveat | B12: test fixture
A13: Gap handling | B13: The ECB publishes on business days only. Weekend and holiday rows carry the previous published rate forward and are flagged in the Rates sheet.
A14: Trend method | B14: Ordinary least squares on rate against date serial, computed live by SLOPE and INTERCEPT so the fit updates if rows are added or removed.
A15: Index method | B15: Each rate divided by the first rate in the series, times 100. Used for the comparison chart because the three pairs differ by orders of magnitude.
